function greet(name) {
  return new Promise((resolve, reject) => {
    setTimeout(() => {
      if (typeof name === 'string') { 
        resolve('hello ' + name);
      } else {
        reject('Greet expects a string!');
      }
    }, 1000);
  });
}

function uppercaser(str) {
  return new Promise((resolve, reject) => {
    setTimeout(() =>{
      if (typeof str === 'string') {
        resolve(str.toUpperCase());
      } else {
        reject('Argument to uppercaser must be string');
      }
    }, 1000);
  });
}


// Above we have two functions that return promises. 
// These are greet and uppercaser. 
// Notice below how we chain these promises together. The 
// Result of one is then passed to the next. 
// When chained all of the promises have to resolve for success. 
// If any of the promises reject then you end in the catch block. 

greet('Your name') // Returns a Promise
  .then(str => uppercaser(str))  // Upper case the results from greet() Returns a Promise
  .then(str => console.log(str)) // Log the results of uppercaser()
  .catch(err => console.log(err)) // Catches an error

// Challenges: get greet() to fail by passing a non string value
// What happens? For some reason the second promis is returned
greet('hello') // Returns a Promise
  .then(str => uppercaser(55))  // Upper case the results from greet() Returns a Promise
  .then(str => console.log(str)) // Log the results of uppercaser()
  .catch(err => console.log(err)) // Catches an error
// Challenge: get uppercaser() to fail by passing a non string value
// What happens? the second block now executes first and a different error is passed through

// Challenge: Notice there is only a single .catch() at the end. 
// Explain the behavior?
// Because the first promise resolves err == null, on the second promise err == the second reject